Workbook

Sheet PL
A1: Monthly Profit & Loss
A2: Amounts in currency units. First month (B4) is an input; later months step forward.
A4: Line | B4: 46023 | C4: =EDATE(B4,1) -> 46054 | D4: =EDATE(C4,1) -> 46082 | E4: =EDATE(D4,1) -> 46113 | F4: Total
A5: Revenue | B5: =SUMIFS(Ledger!$J$2:$J$500,Ledger!$G$2:$G$500,"Revenue",Ledger!$I$2:$I$500,B$4) -> 7000 | C5: =SUMIFS(Ledger!$J$2:$J$500,Ledger!$G$2:$G$500,"Revenue",Ledger!$I$2:$I$500,C$4) -> 6000 | D5: =SUMIFS(Ledger!$J$2:$J$500,Ledger!$G$2:$G$500,"Revenue",Ledger!$I$2:$I$500,D$4) -> 12000 | E5: =SUMIFS(Ledger!$J$2:$J$500,Ledger!$G$2:$G$500,"Revenue",Ledger!$I$2:$I$500,E$4) -> 8000 | F5: =SUM(B5:E5) -> 33000
A6: Cost of goods sold | B6: =SUMIFS(Ledger!$J$2:$J$500,Ledger!$G$2:$G$500,"COGS",Ledger!$I$2:$I$500,B$4) -> 1800 | C6: =SUMIFS(Ledger!$J$2:$J$500,Ledger!$G$2:$G$500,"COGS",Ledger!$I$2:$I$500,C$4) -> 0 | D6: =SUMIFS(Ledger!$J$2:$J$500,Ledger!$G$2:$G$500,"COGS",Ledger!$I$2:$I$500,D$4) -> 0 | E6: =SUMIFS(Ledger!$J$2:$J$500,Ledger!$G$2:$G$500,"COGS",Ledger!$I$2:$I$500,E$4) -> 0 | F6: =SUM(B6:E6) -> 1800
A7: Gross profit | B7: =B5-B6 -> 5200 | C7: =C5-C6 -> 6000 | D7: =D5-D6 -> 12000 | E7: =E5-E6 -> 8000 | F7: =SUM(B7:E7) -> 31200
A8: Operating expenses | B8: =SUMIFS(Ledger!$J$2:$J$500,Ledger!$G$2:$G$500,"Opex",Ledger!$I$2:$I$500,B$4) -> 3500 | C8: =SUMIFS(Ledger!$J$2:$J$500,Ledger!$G$2:$G$500,"Opex",Ledger!$I$2:$I$500,C$4) -> 3300 | D8: =SUMIFS(Ledger!$J$2:$J$500,Ledger!$G$2:$G$500,"Opex",Ledger!$I$2:$I$500,D$4) -> 4100 | E8: =SUMIFS(Ledger!$J$2:$J$500,Ledger!$G$2:$G$500,"Opex",Ledger!$I$2:$I$500,E$4) -> 4100 | F8: =SUM(B8:E8) -> 15000
A9: Net profit | B9: =B7-B8 -> 1700 | C9: =C7-C8 -> 2700 | D9: =D7-D8 -> 7900 | E9: =E7-E8 -> 3900 | F9: =SUM(B9:E9) -> 16200
A11: Unmapped amount excluded from the P&L above (debit+credit lines): | F11: =SUMIFS(Ledger!$D$2:$D$500,Ledger!$H$2:$H$500,"UNMAPPED")+SUMIFS(Ledger!$E$2:$E$500,Ledger!$H$2:$H$500,"UNMAPPED") -> 0

Sheet BS
A1: Balance sheet (month-end)
A4: Balance sheet | B4: =PL!B4 -> 46023 | C4: =PL!C4 -> 46054 | D4: =PL!D4 -> 46082 | E4: =PL!E4 -> 46113
A5: Assets
A6: Cash (account 1000) | B6: =SUMIFS(Ledger!$D$2:$D$500,Ledger!$B$2:$B$500,1000,Ledger!$I$2:$I$500,"<="&B$4)-SUMIFS(Ledger!$E$2:$E$500,Ledger!$B$2:$B$500,1000,Ledger!$I$2:$I$500,"<="&B$4) -> 1700 | C6: =SUMIFS(Ledger!$D$2:$D$500,Ledger!$B$2:$B$500,1000,Ledger!$I$2:$I$500,"<="&C$4)-SUMIFS(Ledger!$E$2:$E$500,Ledger!$B$2:$B$500,1000,Ledger!$I$2:$I$500,"<="&C$4) -> 14400 | D6: =SUMIFS(Ledger!$D$2:$D$500,Ledger!$B$2:$B$500,1000,Ledger!$I$2:$I$500,"<="&D$4)-SUMIFS(Ledger!$E$2:$E$500,Ledger!$B$2:$B$500,1000,Ledger!$I$2:$I$500,"<="&D$4) -> 18500 | E6: =SUMIFS(Ledger!$D$2:$D$500,Ledger!$B$2:$B$500,1000,Ledger!$I$2:$I$500,"<="&E$4)-SUMIFS(Ledger!$E$2:$E$500,Ledger!$B$2:$B$500,1000,Ledger!$I$2:$I$500,"<="&E$4) -> 24700
A7: Accounts receivable (account 1100) | B7: =SUMIFS(Ledger!$D$2:$D$500,Ledger!$B$2:$B$500,1100,Ledger!$I$2:$I$500,"<="&B$4)-SUMIFS(Ledger!$E$2:$E$500,Ledger!$B$2:$B$500,1100,Ledger!$I$2:$I$500,"<="&B$4) -> 0 | C7: =SUMIFS(Ledger!$D$2:$D$500,Ledger!$B$2:$B$500,1100,Ledger!$I$2:$I$500,"<="&C$4)-SUMIFS(Ledger!$E$2:$E$500,Ledger!$B$2:$B$500,1100,Ledger!$I$2:$I$500,"<="&C$4) -> 0 | D7: =SUMIFS(Ledger!$D$2:$D$500,Ledger!$B$2:$B$500,1100,Ledger!$I$2:$I$500,"<="&D$4)-SUMIFS(Ledger!$E$2:$E$500,Ledger!$B$2:$B$500,1100,Ledger!$I$2:$I$500,"<="&D$4) -> 5000 | E7: =SUMIFS(Ledger!$D$2:$D$500,Ledger!$B$2:$B$500,1100,Ledger!$I$2:$I$500,"<="&E$4)-SUMIFS(Ledger!$E$2:$E$500,Ledger!$B$2:$B$500,1100,Ledger!$I$2:$I$500,"<="&E$4) -> 2000
A8: Total assets | B8: =B6+B7 -> 1700 | C8: =C6+C7 -> 14400 | D8: =D6+D7 -> 23500 | E8: =E6+E7 -> 26700
A10: Liabilities
A11: Accounts payable (account 2000) | B11: =SUMIFS(Ledger!$E$2:$E$500,Ledger!$B$2:$B$500,2000,Ledger!$I$2:$I$500,"<="&B$4)-SUMIFS(Ledger!$D$2:$D$500,Ledger!$B$2:$B$500,2000,Ledger!$I$2:$I$500,"<="&B$4) -> 0 | C11: =SUMIFS(Ledger!$E$2:$E$500,Ledger!$B$2:$B$500,2000,Ledger!$I$2:$I$500,"<="&C$4)-SUMIFS(Ledger!$D$2:$D$500,Ledger!$B$2:$B$500,2000,Ledger!$I$2:$I$500,"<="&C$4) -> 0 | D11: =SUMIFS(Ledger!$E$2:$E$500,Ledger!$B$2:$B$500,2000,Ledger!$I$2:$I$500,"<="&D$4)-SUMIFS(Ledger!$D$2:$D$500,Ledger!$B$2:$B$500,2000,Ledger!$I$2:$I$500,"<="&D$4) -> 1200 | E11: =SUMIFS(Ledger!$E$2:$E$500,Ledger!$B$2:$B$500,2000,Ledger!$I$2:$I$500,"<="&E$4)-SUMIFS(Ledger!$D$2:$D$500,Ledger!$B$2:$B$500,2000,Ledger!$I$2:$I$500,"<="&E$4) -> 500
A12: Bank loan (account 2500) | B12: =SUMIFS(Ledger!$E$2:$E$500,Ledger!$B$2:$B$500,2500,Ledger!$I$2:$I$500,"<="&B$4)-SUMIFS(Ledger!$D$2:$D$500,Ledger!$B$2:$B$500,2500,Ledger!$I$2:$I$500,"<="&B$4) -> 0 | C12: =SUMIFS(Ledger!$E$2:$E$500,Ledger!$B$2:$B$500,2500,Ledger!$I$2:$I$500,"<="&C$4)-SUMIFS(Ledger!$D$2:$D$500,Ledger!$B$2:$B$500,2500,Ledger!$I$2:$I$500,"<="&C$4) -> 10000 | D12: =SUMIFS(Ledger!$E$2:$E$500,Ledger!$B$2:$B$500,2500,Ledger!$I$2:$I$500,"<="&D$4)-SUMIFS(Ledger!$D$2:$D$500,Ledger!$B$2:$B$500,2500,Ledger!$I$2:$I$500,"<="&D$4) -> 10000 | E12: =SUMIFS(Ledger!$E$2:$E$500,Ledger!$B$2:$B$500,2500,Ledger!$I$2:$I$500,"<="&E$4)-SUMIFS(Ledger!$D$2:$D$500,Ledger!$B$2:$B$500,2500,Ledger!$I$2:$I$500,"<="&E$4) -> 10000
A13: Total liabilities | B13: =B11+B12 -> 0 | C13: =C11+C12 -> 10000 | D13: =D11+D12 -> 11200 | E13: =E11+E12 -> 10500
A15: Equity
A16: Retained earnings (cumulative net profit) | B16: =SUM(PL!$B$9:B$9) -> 1700 | C16: =SUM(PL!$B$9:C$9) -> 4400 | D16: =SUM(PL!$B$9:D$9) -> 12300 | E16: =SUM(PL!$B$9:E$9) -> 16200
A17: Total equity | B17: =B16 -> 1700 | C17: =C16 -> 4400 | D17: =D16 -> 12300 | E17: =E16 -> 16200
A19: Total liabilities + equity | B19: =B13+B17 -> 1700 | C19: =C13+C17 -> 14400 | D19: =D13+D17 -> 23500 | E19: =E13+E17 -> 26700
A20: Difference (assets - liabilities - equity) | B20: =B8-B19 -> 0 | C20: =C8-C19 -> 0 | D20: =D8-D19 -> 0 | E20: =E8-E19 -> 0
A23: Assumptions: no opening balances; no share capital or fixed assets in the sample data.
A24: Receivables rise when you invoice before being paid; payables rise when you receive a bill before paying it.
A25: Retained earnings = cumulative P&L net profit. An unmapped account breaks the balance, shown in the Difference row.

Sheet CF
A1: Cash flow statement (indirect method)
A4: Cash flow | B4: =PL!B4 -> 46023 | C4: =PL!C4 -> 46054 | D4: =PL!D4 -> 46082 | E4: =PL!E4 -> 46113
A5: Operating activities
A6: Net profit | B6: =PL!B9 -> 1700 | C6: =PL!C9 -> 2700 | D6: =PL!D9 -> 7900 | E6: =PL!E9 -> 3900
A7: (Increase)/decrease in receivables | B7: =-(SUMIFS(Ledger!$D$2:$D$500,Ledger!$B$2:$B$500,1100,Ledger!$I$2:$I$500,B$4)-SUMIFS(Ledger!$E$2:$E$500,Ledger!$B$2:$B$500,1100,Ledger!$I$2:$I$500,B$4)) -> 0 | C7: =-(SUMIFS(Ledger!$D$2:$D$500,Ledger!$B$2:$B$500,1100,Ledger!$I$2:$I$500,C$4)-SUMIFS(Ledger!$E$2:$E$500,Ledger!$B$2:$B$500,1100,Ledger!$I$2:$I$500,C$4)) -> 0 | D7: =-(SUMIFS(Ledger!$D$2:$D$500,Ledger!$B$2:$B$500,1100,Ledger!$I$2:$I$500,D$4)-SUMIFS(Ledger!$E$2:$E$500,Ledger!$B$2:$B$500,1100,Ledger!$I$2:$I$500,D$4)) -> -5000 | E7: =-(SUMIFS(Ledger!$D$2:$D$500,Ledger!$B$2:$B$500,1100,Ledger!$I$2:$I$500,E$4)-SUMIFS(Ledger!$E$2:$E$500,Ledger!$B$2:$B$500,1100,Ledger!$I$2:$I$500,E$4)) -> 3000
A8: Increase/(decrease) in payables | B8: =SUMIFS(Ledger!$E$2:$E$500,Ledger!$B$2:$B$500,2000,Ledger!$I$2:$I$500,B$4)-SUMIFS(Ledger!$D$2:$D$500,Ledger!$B$2:$B$500,2000,Ledger!$I$2:$I$500,B$4) -> 0 | C8: =SUMIFS(Ledger!$E$2:$E$500,Ledger!$B$2:$B$500,2000,Ledger!$I$2:$I$500,C$4)-SUMIFS(Ledger!$D$2:$D$500,Ledger!$B$2:$B$500,2000,Ledger!$I$2:$I$500,C$4) -> 0 | D8: =SUMIFS(Ledger!$E$2:$E$500,Ledger!$B$2:$B$500,2000,Ledger!$I$2:$I$500,D$4)-SUMIFS(Ledger!$D$2:$D$500,Ledger!$B$2:$B$500,2000,Ledger!$I$2:$I$500,D$4) -> 1200 | E8: =SUMIFS(Ledger!$E$2:$E$500,Ledger!$B$2:$B$500,2000,Ledger!$I$2:$I$500,E$4)-SUMIFS(Ledger!$D$2:$D$500,Ledger!$B$2:$B$500,2000,Ledger!$I$2:$I$500,E$4) -> -700
A9: Cash from operations | B9: =SUM(B6:B8) -> 1700 | C9: =SUM(C6:C8) -> 2700 | D9: =SUM(D6:D8) -> 4100 | E9: =SUM(E6:E8) -> 6200
A11: Financing activities
A12: Loan proceeds / (repayments) | B12: =SUMIFS(Ledger!$E$2:$E$500,Ledger!$B$2:$B$500,2500,Ledger!$I$2:$I$500,B$4)-SUMIFS(Ledger!$D$2:$D$500,Ledger!$B$2:$B$500,2500,Ledger!$I$2:$I$500,B$4) -> 0 | C12: =SUMIFS(Ledger!$E$2:$E$500,Ledger!$B$2:$B$500,2500,Ledger!$I$2:$I$500,C$4)-SUMIFS(Ledger!$D$2:$D$500,Ledger!$B$2:$B$500,2500,Ledger!$I$2:$I$500,C$4) -> 10000 | D12: =SUMIFS(Ledger!$E$2:$E$500,Ledger!$B$2:$B$500,2500,Ledger!$I$2:$I$500,D$4)-SUMIFS(Ledger!$D$2:$D$500,Ledger!$B$2:$B$500,2500,Ledger!$I$2:$I$500,D$4) -> 0 | E12: =SUMIFS(Ledger!$E$2:$E$500,Ledger!$B$2:$B$500,2500,Ledger!$I$2:$I$500,E$4)-SUMIFS(Ledger!$D$2:$D$500,Ledger!$B$2:$B$500,2500,Ledger!$I$2:$I$500,E$4) -> 0
A13: Cash from financing | B13: =B12 -> 0 | C13: =C12 -> 10000 | D13: =D12 -> 0 | E13: =E12 -> 0
A15: Net change in cash | B15: =B9+B13 -> 1700 | C15: =C9+C13 -> 12700 | D15: =D9+D13 -> 4100 | E15: =E9+E13 -> 6200
A16: Opening cash | B16: 0 | C16: =B17 -> 1700 | D16: =C17 -> 14400 | E16: =D17 -> 18500
A17: Closing cash | B17: =B16+B15 -> 1700 | C17: =C16+C15 -> 14400 | D17: =D16+D15 -> 18500 | E17: =E16+E15 -> 24700
A19: Cash per balance sheet | B19: =BS!B6 -> 1700 | C19: =BS!C6 -> 14400 | D19: =BS!D6 -> 18500 | E19: =BS!E6 -> 24700
A20: Difference (closing cash - balance sheet cash) | B20: =B17-B19 -> 0 | C20: =C17-C19 -> 0 | D20: =D17-D19 -> 0 | E20: =E17-E19 -> 0
A22: Profit is not cash: an unpaid invoice adds to profit but not cash, so receivables increase is subtracted. An unpaid bill reduces profit but not cash, so payables increase is added back.
A23: Opening cash for the first month (B16) is an input: 0 because the sample company starts at zero. Investing activities omitted (no fixed assets).

Sheet Assumptions
A1: Forecast assumptions
A2: Blue/yellow cells are inputs. These are practice assumptions, not predictions for a real business.
A4: Assumption | B4: Value | C4: Historical reference (Jan-Apr actuals) | D4: Basis / how it is used
A5: Monthly revenue growth | B5: 0.03 | D5: Revenue(t) = Revenue(t-1) x (1 + growth). Jan-Apr revenue was lumpy, so 3% is a judgement.
A6: COGS % of revenue | B6: 0.055 | C6: =SUM(PL!B6:E6)/SUM(PL!B5:E5) -> 0.054545455 | D6: COGS = revenue x this %. Reference is total COGS / total revenue Jan-Apr.
A7: Monthly operating expense growth | B7: 0.01 | D7: Opex(t) = Opex(t-1) x (1 + growth). April opex (4,100) is the base.
A8: Receivable days (DSO) | B8: 10 | C8: =BS!E7/PL!E5*30 -> 7.5 | D8: Receivables = revenue x days / 30. Reference is April receivables vs April revenue.
A9: Payable days (DPO) | B9: 4 | C9: =BS!E11/PL!E8*30 -> 3.6585366 | D9: Payables = operating expenses x days / 30. Reference is April.
A10: Loan repayment per month | B10: 500 | D10: Cash outflow reducing the bank loan, never below zero.
A11: Loan interest rate (annual) | B11: 0.06 | D11: Interest = prior month-end loan x rate / 12. Actuals recorded no interest.
A12: Tax rate on profit before tax | B12: 0.2 | D12: Tax = max(0, profit before tax) x rate, paid in the same month. Actuals recorded no tax.
A15: DCF assumption | B15: Value | C15: Historical reference | D15: Basis / how it is used
A16: WACC (discount rate) | B16: 0.12 | D16: Judgement for a small private business; you must justify it (risk, financing mix, size). Higher = lower value.
A17: Terminal growth rate | B17: 0.025 | D17: Long-run growth after Year 5. Should not exceed long-run economic growth; must be below WACC.
A18: Revenue growth, Year 2 | B18: 0.2 | D18: Year 1 comes from the monthly forecast. Years 2-5 fade toward a mature rate. Judgement.
A19: Revenue growth, Year 3 | B19: 0.15 | D19: Judgement.
A20: Revenue growth, Year 4 | B20: 0.1 | D20: Judgement.
A21: Revenue growth, Year 5 | B21: 0.06 | D21: Judgement.
A22: EBIT margin change per year (points) | B22: 0 | D22: 0 = Year 1 margin held flat in Years 2-5.

Sheet Forecast
A1: Three-statement forecast (May 2026 - Apr 2027)
A2: April 2026 is the last actual month. All forecast months are driven by the Assumptions sheet.
B3: Actual | C3: Forecast | D3: Forecast | E3: Forecast | F3: Forecast | G3: Forecast | H3: Forecast | I3: Forecast | J3: Forecast | K3: Forecast | L3: Forecast | M3: Forecast | N3: Forecast
A4: Line | B4: =PL!E4 -> 46113 | C4: =EDATE(B4,1) -> 46143 | D4: =EDATE(C4,1) -> 46174 | E4: =EDATE(D4,1) -> 46204 | F4: =EDATE(E4,1) -> 46235 | G4: =EDATE(F4,1) -> 46266 | H4: =EDATE(G4,1) -> 46296 | I4: =EDATE(H4,1) -> 46327 | J4: =EDATE(I4,1) -> 46357 | ... N4: =EDATE(M4,1) -> 46478
A5: Income statement
A6: Revenue | B6: =PL!E5 -> 8000 | C6: =B6*(1+Assumptions!$B$5) -> 8240 | D6: =C6*(1+Assumptions!$B$5) -> 8487.2 | E6: =D6*(1+Assumptions!$B$5) -> 8741.816 | F6: =E6*(1+Assumptions!$B$5) -> 9004.0705 | G6: =F6*(1+Assumptions!$B$5) -> 9274.1926 | H6: =G6*(1+Assumptions!$B$5) -> 9552.4184 | I6: =H6*(1+Assumptions!$B$5) -> 9838.9909 | J6: =I6*(1+Assumptions!$B$5) -> 10134.161 | ... N6: =M6*(1+Assumptions!$B$5) -> 11406.087
A7: Cost of goods sold | B7: =PL!E6 -> 0 | C7: =C6*Assumptions!$B$6 -> 453.2 | D7: =D6*Assumptions!$B$6 -> 466.796 | E7: =E6*Assumptions!$B$6 -> 480.79988 | F7: =F6*Assumptions!$B$6 -> 495.22388 | G7: =G6*Assumptions!$B$6 -> 510.08059 | H7: =H6*Assumptions!$B$6 -> 525.38301 | I7: =I6*Assumptions!$B$6 -> 541.1445 | J7: =J6*Assumptions!$B$6 -> 557.37884 | ... N7: =N6*Assumptions!$B$6 -> 627.33479
A8: Gross profit | B8: =B6-B7 -> 8000 | C8: =C6-C7 -> 7786.8 | D8: =D6-D7 -> 8020.404 | E8: =E6-E7 -> 8261.0161 | F8: =F6-F7 -> 8508.8466 | G8: =G6-G7 -> 8764.112 | H8: =H6-H7 -> 9027.0354 | I8: =I6-I7 -> 9297.8464 | ... N8: =N6-N7 -> 10778.752
A9: Operating expenses | B9: =PL!E8 -> 4100 | C9: =B9*(1+Assumptions!$B$7) -> 4141 | D9: =C9*(1+Assumptions!$B$7) -> 4182.41 | E9: =D9*(1+Assumptions!$B$7) -> 4224.2341 | F9: =E9*(1+Assumptions!$B$7) -> 4266.4764 | G9: =F9*(1+Assumptions!$B$7) -> 4309.1412 | H9: =G9*(1+Assumptions!$B$7) -> 4352.2326 | I9: =H9*(1+Assumptions!$B$7) -> 4395.7549 | J9: =I9*(1+Assumptions!$B$7) -> 4439.7125 | ... N9: =M9*(1+Assumptions!$B$7) -> 4619.9826
A10: Operating profit | B10: =B8-B9 -> 3900 | C10: =C8-C9 -> 3645.8 | D10: =D8-D9 -> 3837.994 | E10: =E8-E9 -> 4036.782 | F10: =F8-F9 -> 4242.3702 | G10: =G8-G9 -> 4454.9708 | H10: =H8-H9 -> 4674.8027 | I10: =I8-I9 -> 4902.0915 | ... N10: =N8-N9 -> 6158.7697
A11: Interest expense | B11: 0 | C11: =B21*Assumptions!$B$11/12 -> 50 | D11: =C21*Assumptions!$B$11/12 -> 47.5 | E11: =D21*Assumptions!$B$11/12 -> 45 | F11: =E21*Assumptions!$B$11/12 -> 42.5 | G11: =F21*Assumptions!$B$11/12 -> 40 | H11: =G21*Assumptions!$B$11/12 -> 37.5 | I11: =H21*Assumptions!$B$11/12 -> 35 | J11: =I21*Assumptions!$B$11/12 -> 32.5 | ... N11: =M21*Assumptions!$B$11/12 -> 22.5
A12: Profit before tax | B12: =B10-B11 -> 3900 | C12: =C10-C11 -> 3595.8 | D12: =D10-D11 -> 3790.494 | E12: =E10-E11 -> 3991.782 | F12: =F10-F11 -> 4199.8702 | G12: =G10-G11 -> 4414.9708 | H12: =H10-H11 -> 4637.3027 | I12: =I10-I11 -> 4867.0915 | ... N12: =N10-N11 -> 6136.2697
A13: Tax | B13: 0 | C13: =MAX(0,C12)*Assumptions!$B$12 -> 719.16 | D13: =MAX(0,D12)*Assumptions!$B$12 -> 758.0988 | E13: =MAX(0,E12)*Assumptions!$B$12 -> 798.3564 | F13: =MAX(0,F12)*Assumptions!$B$12 -> 839.97403 | G13: =MAX(0,G12)*Assumptions!$B$12 -> 882.99416 | H13: =MAX(0,H12)*Assumptions!$B$12 -> 927.46055 | I13: =MAX(0,I12)*Assumptions!$B$12 -> 973.4183 | J13: =MAX(0,J12)*Assumptions!$B$12 -> 1020.9139 | ... N13: =MAX(0,N12)*Assumptions!$B$12 -> 1227.2539
A14: Net profit | B14: =B12-B13 -> 3900 | C14: =C12-C13 -> 2876.64 | D14: =D12-D13 -> 3032.3952 | E14: =E12-E13 -> 3193.4256 | F14: =F12-F13 -> 3359.8961 | G14: =G12-G13 -> 3531.9766 | H14: =H12-H13 -> 3709.8422 | I14: =I12-I13 -> 3893.6732 | ... N14: =N12-N13 -> 4909.0157
A16: Balance sheet
A17: Cash | B17: =BS!E6 -> 24700 | C17: =C34 -> 26382.107 | D17: =D34 -> 28837.623 | E17: =E34 -> 31451.753 | F17: =F34 -> 34229.864 | G17: =G34 -> 37177.488 | H17: =H34 -> 40300.334 | I17: =I34 -> 43604.286 | J17: =J34 -> 47095.413 | ... N17: =N34 -> 63059.769
A18: Accounts receivable | B18: =BS!E7 -> 2000 | C18: =C6*Assumptions!$B$8/30 -> 2746.6667 | D18: =D6*Assumptions!$B$8/30 -> 2829.0667 | E18: =E6*Assumptions!$B$8/30 -> 2913.9387 | F18: =F6*Assumptions!$B$8/30 -> 3001.3568 | G18: =G6*Assumptions!$B$8/30 -> 3091.3975 | H18: =H6*Assumptions!$B$8/30 -> 3184.1395 | I18: =I6*Assumptions!$B$8/30 -> 3279.6636 | J18: =J6*Assumptions!$B$8/30 -> 3378.0536 | ... N18: =N6*Assumptions!$B$8/30 -> 3802.029
A19: Total assets | B19: =B17+B18 -> 26700 | C19: =C17+C18 -> 29128.773 | D19: =D17+D18 -> 31666.69 | E19: =E17+E18 -> 34365.692 | F19: =F17+F18 -> 37231.22 | G19: =G17+G18 -> 40268.886 | H19: =H17+H18 -> 43484.473 | I19: =I17+I18 -> 46883.95 | ... N19: =N17+N18 -> 66861.798
A20: Accounts payable | B20: =BS!E11 -> 500 | C20: =C9*Assumptions!$B$9/30 -> 552.13333 | D20: =D9*Assumptions!$B$9/30 -> 557.65467 | E20: =E9*Assumptions!$B$9/30 -> 563.23121 | F20: =F9*Assumptions!$B$9/30 -> 568.86353 | G20: =G9*Assumptions!$B$9/30 -> 574.55216 | H20: =H9*Assumptions!$B$9/30 -> 580.29768 | I20: =I9*Assumptions!$B$9/30 -> 586.10066 | J20: =J9*Assumptions!$B$9/30 -> 591.96167 | ... N20: =N9*Assumptions!$B$9/30 -> 615.99768
A21: Bank loan | B21: =BS!E12 -> 10000 | C21: =MAX(0,B21-Assumptions!$B$10) -> 9500 | D21: =MAX(0,C21-Assumptions!$B$10) -> 9000 | E21: =MAX(0,D21-Assumptions!$B$10) -> 8500 | F21: =MAX(0,E21-Assumptions!$B$10) -> 8000 | G21: =MAX(0,F21-Assumptions!$B$10) -> 7500 | H21: =MAX(0,G21-Assumptions!$B$10) -> 7000 | I21: =MAX(0,H21-Assumptions!$B$10) -> 6500 | J21: =MAX(0,I21-Assumptions!$B$10) -> 6000 | ... N21: =MAX(0,M21-Assumptions!$B$10) -> 4000
A22: Retained earnings | B22: =BS!E16 -> 16200 | C22: =B22+C14 -> 19076.64 | D22: =C22+D14 -> 22109.035 | E22: =D22+E14 -> 25302.461 | F22: =E22+F14 -> 28662.357 | G22: =F22+G14 -> 32194.334 | H22: =G22+H14 -> 35904.176 | I22: =H22+I14 -> 39797.849 | J22: =I22+J14 -> 43881.504 | ... N22: =M22+N14 -> 62245.801
A23: Total liabilities + equity | B23: =B20+B21+B22 -> 26700 | C23: =C20+C21+C22 -> 29128.773 | D23: =D20+D21+D22 -> 31666.69 | E23: =E20+E21+E22 -> 34365.692 | F23: =F20+F21+F22 -> 37231.22 | G23: =G20+G21+G22 -> 40268.886 | H23: =H20+H21+H22 -> 43484.473 | I23: =I20+I21+I22 -> 46883.95 | ... N23: =N20+N21+N22 -> 66861.798
A24: Difference (assets - liabilities - equity) | B24: =ROUND(B19-B23,2) -> 0 | C24: =ROUND(C19-C23,2) -> 0 | D24: =ROUND(D19-D23,2) -> 0 | E24: =ROUND(E19-E23,2) -> 0 | F24: =ROUND(F19-F23,2) -> 0 | G24: =ROUND(G19-G23,2) -> 0 | H24: =ROUND(H19-H23,2) -> 0 | I24: =ROUND(I19-I23,2) -> 0 | ... N24: =ROUND(N19-N23,2) -> 0
A26: Cash flow
A27: Net profit | C27: =C14 -> 2876.64 | D27: =D14 -> 3032.3952 | E27: =E14 -> 3193.4256 | F27: =F14 -> 3359.8961 | G27: =G14 -> 3531.9766 | H27: =H14 -> 3709.8422 | I27: =I14 -> 3893.6732 | J27: =J14 -> 4083.6555 | ... N27: =N14 -> 4909.0157
A28: (Increase)/decrease in receivables | C28: =-(C18-B18) -> -746.66667 | D28: =-(D18-C18) -> -82.4 | E28: =-(E18-D18) -> -84.872 | F28: =-(F18-E18) -> -87.41816 | G28: =-(G18-F18) -> -90.040705 | H28: =-(H18-G18) -> -92.741926 | I28: =-(I18-H18) -> -95.524184 | J28: =-(J18-I18) -> -98.389909 | ... N28: =-(N18-M18) -> -110.73871
A29: Increase/(decrease) in payables | C29: =C20-B20 -> 52.133333 | D29: =D20-C20 -> 5.5213333 | E29: =E20-D20 -> 5.5765467 | F29: =F20-E20 -> 5.6323121 | G29: =G20-F20 -> 5.6886353 | H29: =H20-G20 -> 5.7455216 | I29: =I20-H20 -> 5.8029768 | J29: =J20-I20 -> 5.8610066 | ... N29: =N20-M20 -> 6.098987
A30: Cash from operations | C30: =SUM(C27:C29) -> 2182.1067 | D30: =SUM(D27:D29) -> 2955.5165 | E30: =SUM(E27:E29) -> 3114.1302 | F30: =SUM(F27:F29) -> 3278.1103 | G30: =SUM(G27:G29) -> 3447.6246 | H30: =SUM(H27:H29) -> 3622.8458 | I30: =SUM(I27:I29) -> 3803.952 | J30: =SUM(J27:J29) -> 3991.1266 | ... N30: =SUM(N27:N29) -> 4804.376
A31: Loan proceeds / (repayments) | C31: =C21-B21 -> -500 | D31: =D21-C21 -> -500 | E31: =E21-D21 -> -500 | F31: =F21-E21 -> -500 | G31: =G21-F21 -> -500 | H31: =H21-G21 -> -500 | I31: =I21-H21 -> -500 | J31: =J21-I21 -> -500 | ... N31: =N21-M21 -> -500
A32: Net change in cash | C32: =C30+C31 -> 1682.1067 | D32: =D30+D31 -> 2455.5165 | E32: =E30+E31 -> 2614.1302 | F32: =F30+F31 -> 2778.1103 | G32: =G30+G31 -> 2947.6246 | H32: =H30+H31 -> 3122.8458 | I32: =I30+I31 -> 3303.952 | J32: =J30+J31 -> 3491.1266 | ... N32: =N30+N31 -> 4304.376
A33: Opening cash | C33: =B34 -> 24700 | D33: =C34 -> 26382.107 | E33: =D34 -> 28837.623 | F33: =E34 -> 31451.753 | G33: =F34 -> 34229.864 | H33: =G34 -> 37177.488 | I33: =H34 -> 40300.334 | J33: =I34 -> 43604.286 | ... N33: =M34 -> 58755.393
A34: Closing cash | B34: =BS!E6 -> 24700 | C34: =C33+C32 -> 26382.107 | D34: =D33+D32 -> 28837.623 | E34: =E33+E32 -> 31451.753 | F34: =F33+F32 -> 34229.864 | G34: =G33+G32 -> 37177.488 | H34: =H33+H32 -> 40300.334 | I34: =I33+I32 -> 43604.286 | J34: =J33+J32 -> 47095.413 | ... N34: =N33+N32 -> 63059.769
A36: Gross margin % | B36: =IF(B6=0,0,B8/B6) -> 1 | C36: =IF(C6=0,0,C8/C6) -> 0.945 | D36: =IF(D6=0,0,D8/D6) -> 0.945 | E36: =IF(E6=0,0,E8/E6) -> 0.945 | F36: =IF(F6=0,0,F8/F6) -> 0.945 | G36: =IF(G6=0,0,G8/G6) -> 0.945 | H36: =IF(H6=0,0,H8/H6) -> 0.945 | I36: =IF(I6=0,0,I8/I6) -> 0.945 | ... N36: =IF(N6=0,0,N8/N6) -> 0.945
A37: Net margin % | B37: =IF(B6=0,0,B14/B6) -> 0.4875 | C37: =IF(C6=0,0,C14/C6) -> 0.3491068 | D37: =IF(D6=0,0,D14/D6) -> 0.35729041 | E37: =IF(E6=0,0,E14/E6) -> 0.3653046 | F37: =IF(F6=0,0,F14/F6) -> 0.37315302 | G37: =IF(G6=0,0,G14/G6) -> 0.38083926 | H37: =IF(H6=0,0,H14/H6) -> 0.3883668 | I37: =IF(I6=0,0,I14/I6) -> 0.39573908 | ... N37: =IF(N6=0,0,N14/N6) -> 0.43038561
A39: Actual column: interest and tax are 0 because none were recorded in the ledger. Cash in each forecast month comes from the cash flow statement, so the balance check tests the logic.

Sheet DCF
A1: Discounted cash flow valuation
A2: Valuation date: 30 Apr 2026 (last actual month). Year 1 = May 2026 - Apr 2027 from the Forecast sheet. Year-end discounting. Practice model: based on 4 months of data.
A4: Unlevered free cash flow | B4: Year 1 | C4: Year 2 | D4: Year 3 | E4: Year 4 | F4: Year 5
A6: Revenue | B6: =SUM(Forecast!C6:N6) -> 116942.32 | C6: =B6*(1+C7) -> 140330.79 | D6: =C6*(1+D7) -> 161380.41 | E6: =D6*(1+E7) -> 177518.45 | F6: =E6*(1+F7) -> 188169.55
A7: Revenue growth | B7: n/a | C7: =Assumptions!B18 -> 0.2 | D7: =Assumptions!B19 -> 0.15 | E7: =Assumptions!B20 -> 0.1 | F7: =Assumptions!B21 -> 0.06
A8: EBIT (operating profit) | B8: =SUM(Forecast!C10:N10) -> 57992.251 | C8: =C6*C9 -> 69590.701 | D8: =D6*D9 -> 80029.306 | E8: =E6*E9 -> 88032.237 | F8: =F6*F9 -> 93314.171
A9: EBIT margin | B9: =IF(B6=0,0,B8/B6) -> 0.49590472 | C9: =B9+Assumptions!$B$22 -> 0.49590472 | D9: =C9+Assumptions!$B$22 -> 0.49590472 | E9: =D9+Assumptions!$B$22 -> 0.49590472 | F9: =E9+Assumptions!$B$22 -> 0.49590472
A10: Tax on EBIT | B10: =-MAX(0,B8)*Assumptions!$B$12 -> -11598.45 | C10: =-MAX(0,C8)*Assumptions!$B$12 -> -13918.14 | D10: =-MAX(0,D8)*Assumptions!$B$12 -> -16005.861 | E10: =-MAX(0,E8)*Assumptions!$B$12 -> -17606.447 | F10: =-MAX(0,F8)*Assumptions!$B$12 -> -18662.834
A11: NOPAT (EBIT after tax) | B11: =B8+B10 -> 46393.801 | C11: =C8+C10 -> 55672.561 | D11: =D8+D10 -> 64023.445 | E11: =E8+E10 -> 70425.789 | F11: =F8+F10 -> 74651.337
A12: Change in working capital (cash effect) | B12: =SUM(Forecast!C28:N29) -> -1686.0313 | C12: =-(C6-B6)*$B$32 -> -637.20627 | D12: =-(D6-C6)*$B$32 -> -573.48564 | E12: =-(E6-D6)*$B$32 -> -439.67233 | F12: =-(F6-E6)*$B$32 -> -290.18374
A13: Unlevered free cash flow | B13: =B11+B12 -> 44707.769 | C13: =C11+C12 -> 55035.355 | D13: =D11+D12 -> 63449.959 | E13: =E11+E12 -> 69986.117 | F13: =F11+F12 -> 74361.153
A14: Discount period (years) | B14: 1 | C14: =B14+1 -> 2 | D14: =C14+1 -> 3 | E14: =D14+1 -> 4 | F14: =E14+1 -> 5
A15: Discount factor | B15: =1/(1+Assumptions!$B$16)^B14 -> 0.89285714 | C15: =1/(1+Assumptions!$B$16)^C14 -> 0.79719388 | D15: =1/(1+Assumptions!$B$16)^D14 -> 0.71178025 | E15: =1/(1+Assumptions!$B$16)^E14 -> 0.63551808 | F15: =1/(1+Assumptions!$B$16)^F14 -> 0.56742686
A16: Present value of free cash flow | B16: =B13*B15 -> 39917.651 | C16: =C13*C15 -> 43873.848 | D16: =D13*D15 -> 45162.428 | E16: =E13*E15 -> 44477.443 | F16: =F13*F15 -> 42194.515
A18: Valuation
A19: Sum of PV of free cash flows (Years 1-5) | B19: =SUM(B16:F16) -> 215625.88
A20: Terminal-year free cash flow (Year 5) | B20: =F13 -> 74361.153
A21: Terminal value at end of Year 5 | B21: =IF(Assumptions!B16>Assumptions!B17,F13*(1+Assumptions!B17)/(Assumptions!B16-Assumptions!B17),0) -> 802317.7
A22: PV of terminal value | B22: =B21*F15 -> 455256.61
A23: Enterprise value | B23: =B19+B22 -> 670882.5
A24: Less: bank loan (Apr 2026) | B24: =BS!E12 -> 10000
A25: Plus: cash (Apr 2026) | B25: =BS!E6 -> 24700
A26: Equity value | B26: =B23-B24+B25 -> 685582.5
A27: Terminal value as % of enterprise value | B27: =IF(B23=0,0,B22/B23) -> 0.67859366
A28: Implied EV / Year 1 revenue | B28: =IF(B6=0,0,B23/B6) -> 5.7368665
A29: Implied EV / Year 1 EBIT | B29: =IF(B8>0,B23/B8,0) -> 11.568485
A32: NWC % of Year 1 revenue (used for Years 2-5) | B32: =IF(B6=0,0,(Forecast!N18-Forecast!N20)/B6) -> 0.027244468
A34: Equity value sensitivity: WACC (down) vs terminal growth (across)
A35: WACC \ growth | B35: =Assumptions!$B$17+(-0.01) -> 0.015 | C35: =Assumptions!$B$17+(-0.005) -> 0.02 | D35: =Assumptions!$B$17 -> 0.025 | E35: =Assumptions!$B$17+(0.005) -> 0.03 | F35: =Assumptions!$B$17+(0.01) -> 0.035
A36: =Assumptions!$B$16+(-0.02) -> 0.1 | B36: =IF($A36>B$35,SUMPRODUCT($B$13:$F$13/(1+$A36)^$B$14:$F$14)+$F$13*(1+B$35)/($A36-B$35)/(1+$A36)^$F$14-$B$24+$B$25,"n/a") -> 793825.05 | C36: =IF($A36>C$35,SUMPRODUCT($B$13:$F$13/(1+$A36)^$B$14:$F$14)+$F$13*(1+C$35)/($A36-C$35)/(1+$A36)^$F$14-$B$24+$B$25,"n/a") -> 831170.39 | D36: =IF($A36>D$35,SUMPRODUCT($B$13:$F$13/(1+$A36)^$B$14:$F$14)+$F$13*(1+D$35)/($A36-D$35)/(1+$A36)^$F$14-$B$24+$B$25,"n/a") -> 873495.12 | E36: =IF($A36>E$35,SUMPRODUCT($B$13:$F$13/(1+$A36)^$B$14:$F$14)+$F$13*(1+E$35)/($A36-E$35)/(1+$A36)^$F$14-$B$24+$B$25,"n/a") -> 921866.23 | F36: =IF($A36>F$35,SUMPRODUCT($B$13:$F$13/(1+$A36)^$B$14:$F$14)+$F$13*(1+F$35)/($A36-F$35)/(1+$A36)^$F$14-$B$24+$B$25,"n/a") -> 977679.05
A37: =Assumptions!$B$16+(-0.01) -> 0.11 | B37: =IF($A37>B$35,SUMPRODUCT($B$13:$F$13/(1+$A37)^$B$14:$F$14)+$F$13*(1+B$35)/($A37-B$35)/(1+$A37)^$F$14-$B$24+$B$25,"n/a") -> 707762.28 | C37: =IF($A37>C$35,SUMPRODUCT($B$13:$F$13/(1+$A37)^$B$14:$F$14)+$F$13*(1+C$35)/($A37-C$35)/(1+$A37)^$F$14-$B$24+$B$25,"n/a") -> 736407.89 | D37: =IF($A37>D$35,SUMPRODUCT($B$13:$F$13/(1+$A37)^$B$14:$F$14)+$F$13*(1+D$35)/($A37-D$35)/(1+$A37)^$F$14-$B$24+$B$25,"n/a") -> 768423.58 | E37: =IF($A37>E$35,SUMPRODUCT($B$13:$F$13/(1+$A37)^$B$14:$F$14)+$F$13*(1+E$35)/($A37-E$35)/(1+$A37)^$F$14-$B$24+$B$25,"n/a") -> 804441.22 | F37: =IF($A37>F$35,SUMPRODUCT($B$13:$F$13/(1+$A37)^$B$14:$F$14)+$F$13*(1+F$35)/($A37-F$35)/(1+$A37)^$F$14-$B$24+$B$25,"n/a") -> 845261.21
A38: =Assumptions!$B$16 -> 0.12 | B38: =IF($A38>B$35,SUMPRODUCT($B$13:$F$13/(1+$A38)^$B$14:$F$14)+$F$13*(1+B$35)/($A38-B$35)/(1+$A38)^$F$14-$B$24+$B$25,"n/a") -> 638206.2 | C38: =IF($A38>C$35,SUMPRODUCT($B$13:$F$13/(1+$A38)^$B$14:$F$14)+$F$13*(1+C$35)/($A38-C$35)/(1+$A38)^$F$14-$B$24+$B$25,"n/a") -> 660709.94 | D38: =IF($A38>D$35,SUMPRODUCT($B$13:$F$13/(1+$A38)^$B$14:$F$14)+$F$13*(1+D$35)/($A38-D$35)/(1+$A38)^$F$14-$B$24+$B$25,"n/a") -> 685582.5 | E38: =IF($A38>E$35,SUMPRODUCT($B$13:$F$13/(1+$A38)^$B$14:$F$14)+$F$13*(1+E$35)/($A38-E$35)/(1+$A38)^$F$14-$B$24+$B$25,"n/a") -> 713218.67 | F38: =IF($A38>F$35,SUMPRODUCT($B$13:$F$13/(1+$A38)^$B$14:$F$14)+$F$13*(1+F$35)/($A38-F$35)/(1+$A38)^$F$14-$B$24+$B$25,"n/a") -> 744106.16
A39: =Assumptions!$B$16+(0.01) -> 0.13 | B39: =IF($A39>B$35,SUMPRODUCT($B$13:$F$13/(1+$A39)^$B$14:$F$14)+$F$13*(1+B$35)/($A39-B$35)/(1+$A39)^$F$14-$B$24+$B$25,"n/a") -> 580846.33 | C39: =IF($A39>C$35,SUMPRODUCT($B$13:$F$13/(1+$A39)^$B$14:$F$14)+$F$13*(1+C$35)/($A39-C$35)/(1+$A39)^$F$14-$B$24+$B$25,"n/a") -> 598872.84 | D39: =IF($A39>D$35,SUMPRODUCT($B$13:$F$13/(1+$A39)^$B$14:$F$14)+$F$13*(1+D$35)/($A39-D$35)/(1+$A39)^$F$14-$B$24+$B$25,"n/a") -> 618616.17 | E39: =IF($A39>E$35,SUMPRODUCT($B$13:$F$13/(1+$A39)^$B$14:$F$14)+$F$13*(1+E$35)/($A39-E$35)/(1+$A39)^$F$14-$B$24+$B$25,"n/a") -> 640333.83 | F39: =IF($A39>F$35,SUMPRODUCT($B$13:$F$13/(1+$A39)^$B$14:$F$14)+$F$13*(1+F$35)/($A39-F$35)/(1+$A39)^$F$14-$B$24+$B$25,"n/a") -> 664337.56
A40: =Assumptions!$B$16+(0.02) -> 0.14 | B40: =IF($A40>B$35,SUMPRODUCT($B$13:$F$13/(1+$A40)^$B$14:$F$14)+$F$13*(1+B$35)/($A40-B$35)/(1+$A40)^$F$14-$B$24+$B$25,"n/a") -> 532751.75 | C40: =IF($A40>C$35,SUMPRODUCT($B$13:$F$13/(1+$A40)^$B$14:$F$14)+$F$13*(1+C$35)/($A40-C$35)/(1+$A40)^$F$14-$B$24+$B$25,"n/a") -> 547427.68 | D40: =IF($A40>D$35,SUMPRODUCT($B$13:$F$13/(1+$A40)^$B$14:$F$14)+$F$13*(1+D$35)/($A40-D$35)/(1+$A40)^$F$14-$B$24+$B$25,"n/a") -> 563379.77 | E40: =IF($A40>E$35,SUMPRODUCT($B$13:$F$13/(1+$A40)^$B$14:$F$14)+$F$13*(1+E$35)/($A40-E$35)/(1+$A40)^$F$14-$B$24+$B$25,"n/a") -> 580782.05 | F40: =IF($A40>F$35,SUMPRODUCT($B$13:$F$13/(1+$A40)^$B$14:$F$14)+$F$13*(1+F$35)/($A40-F$35)/(1+$A40)^$F$14-$B$24+$B$25,"n/a") -> 599841.69
A42: Free cash flow = EBIT x (1 - tax) minus the investment in working capital. Interest is excluded (unlevered); debt is deducted in the bridge to equity value.
A43: No depreciation or capex: the sample company has no fixed assets. A real model needs both.
A44: Year 1 uses the Forecast sheet (EBIT and working-capital cash effects). The tax here is on EBIT, so it differs slightly from forecast tax, which is on profit after interest.
A45: All cash is treated as excess cash and added to equity value. The terminal value assumes cash flows grow at the terminal rate forever.

Sheet Checks
A1: Control checks
A3: Check | B3: Result | C3: Expected | D3: Pass? | E3: Note
A4: Debits minus credits | B4: =SUM(Ledger!D2:D500)-SUM(Ledger!E2:E500) -> 0 | C4: 0 | D4: =IF(B4=C4,"PASS","FAIL") -> PASS | E4: Double-entry must balance.
A5: Unmapped ledger lines | B5: =COUNTIF(Ledger!H2:H500,"UNMAPPED") -> 0 | C5: 0 | D5: =IF(B5=C5,"PASS","FAIL") -> PASS | E5: Add the account code to Accounts.
A6: First unmapped account code | B6: {=IFERROR(INDEX(Ledger!B2:B500,MATCH("UNMAPPED",Ledger!H2:H500,0)),"none")} -> none | C6: none | D6: =IF(B6=C6,"PASS","FAIL") -> PASS | E6: Informational.
A7: P&L net profit minus whole-ledger profit | B7: =PL!F9-(SUMIFS(Ledger!J2:J500,Ledger!G2:G500,"Revenue")-SUMIFS(Ledger!J2:J500,Ledger!G2:G500,"COGS")-SUMIFS(Ledger!J2:J500,Ledger!G2:G500,"Opex")) -> 0 | C7: 0 | D7: =IF(B7=C7,"PASS","FAIL") -> PASS | E7: Non-zero means transactions fall outside the 4 months shown in PL.
A8: Net debt-account movement (acct 2500) | B8: =SUMIFS(Ledger!E2:E500,Ledger!B2:B500,2500)-SUMIFS(Ledger!D2:D500,Ledger!B2:B500,2500) -> 10000 | C8: 10000 | D8: =IF(B8=C8,"PASS","FAIL") -> PASS | E8: Loan raises debt by 10,000 (sample data).
A9: Feb 2026 net profit (loan test) | B9: =PL!C9 -> 2700 | C9: 2700 | D9: =IF(B9=C9,"PASS","FAIL") -> PASS | E9: Must be 2,700, not 12,700. Sample-data test.
A10: Balance sheet balances (all months) | B10: =SUMPRODUCT(ABS(BS!B20:E20)) -> 0 | C10: 0 | D10: =IF(B10=C10,"PASS","FAIL") -> PASS | E10: Assets = liabilities + equity in every month.
A11: Cash flow closing cash = balance sheet cash | B11: =SUMPRODUCT(ABS(CF!B20:E20)) -> 0 | C11: 0 | D11: =IF(B11=C11,"PASS","FAIL") -> PASS | E11: Cash flow statement must tie to the balance sheet.
A12: Other balance sheet accounts (not 1000/1100/2000/2500) | B12: =COUNTIFS(Ledger!G2:G500,"Balance Sheet",Ledger!B2:B500,"<>1000",Ledger!B2:B500,"<>1100",Ledger!B2:B500,"<>2000",Ledger!B2:B500,"<>2500") -> 0 | C12: 0 | D12: =IF(B12=C12,"PASS","FAIL") -> PASS | E12: BS and CF only show these four; extend them if above 0.
A13: Mar 2026 receivables (sample test) | B13: =BS!D7 -> 5000 | C13: 5000 | D13: =IF(B13=C13,"PASS","FAIL") -> PASS | E13: Unpaid 5,000 invoice. Sample-data test.
A14: Forecast balance sheet balances | B14: =ROUND(SUMPRODUCT(ABS(Forecast!B24:N24)),2) -> 0 | C14: 0 | D14: =IF(B14=C14,"PASS","FAIL") -> PASS | E14: Forecast assets = liabilities + equity every month.
A15: Forecast base month net profit - actual April | B15: =ROUND(Forecast!B14-PL!E9,2) -> 0 | C15: 0 | D15: =IF(B15=C15,"PASS","FAIL") -> PASS | E15: Forecast starts from the actual April result.
A16: Forecast months with negative cash | B16: =COUNTIF(Forecast!C17:N17,"<0") -> 0 | C16: 0 | D16: =IF(B16=C16,"PASS","FAIL") -> PASS | E16: A negative month means the assumptions need a funding plan.
A17: DCF: WACC above terminal growth | B17: =IF(Assumptions!B16>Assumptions!B17,0,1) -> 0 | C17: 0 | D17: =IF(B17=C17,"PASS","FAIL") -> PASS | E17: The terminal value formula needs WACC > g.
A18: DCF: sensitivity centre = equity value | B18: =ROUND(DCF!D38-DCF!B26,2) -> 0 | C18: 0 | D18: =IF(B18=C18,"PASS","FAIL") -> PASS | E18: The grid recomputes the valuation independently.
A19: DCF: terminal value over 85% of EV (flag) | B19: =IF(DCF!B27>0.85,1,0) -> 0 | C19: 0 | D19: =IF(B19=C19,"PASS","FAIL") -> PASS | E19: A high share means the value rests on the far future.
A21: OVERALL STATUS | B21: =IF(COUNTIF(D4:D19,"FAIL")=0,"ALL CHECKS PASS",COUNTIF(D4:D19,"FAIL")&" CHECK(S) FAILING") -> ALL CHECKS PASS
A23: Blue Expected values are inputs for the sample data; replace them if you use your own.

Sheet Practice_Log
A1: Practice log - results from actually running each step
A3: Step 1 Net profit Jan/Feb/Mar as delivered | B3: 1,700 / 2,700 / 4,500 - matched
A4: Step 2 Loan (Feb, accts 1000 & 2500) | B4: Category = Balance Sheet, PLAmount = 0. A loan raises cash and debt, not profit. Feb profit stays 2,700.
A5: Step 3 Mapped 6900 Travel as Opex | B5: Mar profit 4,500 -> 4,100. Unmapped count 1 -> 0.
A6: Step 4 Added April (8 lines) | B6: Apr profit = 3,900. All checks PASS. Net profit Jan-Apr: 1,700 / 2,700 / 4,100 / 3,900.
A7: Step 5 Changed 6200 Marketing from Opex to COGS | B7: Feb gross profit 6,000 -> 5,200; Feb net profit unchanged at 2,700. Apr gross profit 8,000 -> 7,400; net 3,900 unchanged. Lesson: classification changes gross profit, not net profit. (This workbook is saved with Marketing back as Opex.)
A8: Step 6 Added an unbalanced 500 debit (rent, no credit) | B8: Only 'Debits minus credits' FAILED (500). Unmapped and tie-out checks still passed, so this check is the only guard against one-sided entries. (Test row not saved in this workbook.)
A12: Working-capital step (added after the practice steps above)
A13: Added 8 ledger lines: Mar unpaid 5,000 invoice (Dr 1100 / Cr 4100) and unpaid 1,200 marketing bill (Dr 6200 / Cr 2000); Apr customer pays 3,000 and 700 paid to supplier.
A14: Profit now: Jan 1,700 | Feb 2,700 | Mar 7,900 | Apr 3,900. The earlier figure of Mar 4,100 is superseded because of the new invoice and bill.

Sheet README
A1: Automated Monthly P&L
A3: HOW IT WORKS
A4: Accounts - chart of accounts. Add new account codes here (blue = input).
A5: Ledger - paste transactions into columns A:E (Date, AccountCode, Description, Debit, Credit). Columns F:J are formulas, prefilled to row 500.
A6: PL - monthly P&L built with SUMIFS from Ledger. Change the first month in PL!B4 to shift the window.
A7: Checks - debits=credits, unmapped accounts, profit tie-out, loan test. Status turns red if anything fails.
A9: ACCOUNTING RULES BUILT IN (Ledger column J, PLAmount)
A10: Revenue = Credit - Debit. COGS and Opex = Debit - Credit. Balance Sheet accounts = 0 (loans, cash do not touch profit).
A12: TO ADD A MONTH: paste the new rows (e.g. from 2026-04_TEST_ONLY.csv) under the last Ledger row, in A:E. PL and Checks update automatically.
A13: TO CLEAR THE UNMAPPED FLAG: add 6900 / Travel / Opex to the Accounts sheet.
A15: EXPECTED RESULTS (sample data): Jan profit 1,700 | Feb profit 2,700 (10,000 loan excluded) | Mar profit 4,500 with 400 unmapped (becomes 4,100 once 6900 is mapped as Opex) | Apr profit 3,900 once added.
A17: NOTE: Power Query folder import cannot be authored from outside Excel. The Power Query version is in LedgerQuery.pq; paste it into Advanced Editor if you want folder import. The Ledger sheet works without it.
... A26: DCF: Assumptions (DCF block) drives DCF (free cash flow, valuation, sensitivity). Overall check status is in Checks (OVERALL STATUS row).

Sheet Accounts
A1: AccountCode | B1: AccountName | C1: Category | E1: Valid categories: Revenue, COGS, Opex, Balance Sheet. Lookups read rows 2-100.
A2: 1000 | B2: Cash | C2: Balance Sheet
A3: 2500 | B3: Bank Loan | C3: Balance Sheet
A4: 4000 | B4: Product Sales | C4: Revenue
A5: 4100 | B5: Service Revenue | C5: Revenue
A6: 5000 | B6: Cost of Goods Sold | C6: COGS
A7: 6000 | B7: Salaries | C7: Opex
A8: 6100 | B8: Rent | C8: Opex
A9: 6200 | B9: Marketing | C9: Opex
A10: 6900 | B10: Travel | C10: Opex
A11: 1100 | B11: Accounts Receivable | C11: Balance Sheet
A12: 2000 | B12: Accounts Payable | C12: Balance Sheet

Sheet Ledger
A1: Date | B1: AccountCode | C1: Description | D1: Debit | E1: Credit | F1: AccountName | G1: Category | H1: Status | I1: Month | J1: PLAmount
A2: 46027 | B2: 1000 | C2: Product sale | D2: 5000 | F2: {=IF($B2="","",IFERROR(INDEX(Accounts!$B$2:$B$100,MATCH($B2,Accounts!$A$2:$A$100,0)),""))} -> Cash | G2: {=IF($B2="","",IFERROR(INDEX(Accounts!$C$2:$C$100,MATCH($B2,Accounts!$A$2:$A$100,0)),""))} -> Balance Sheet | H2: =IF($B2="","",IF(G2="","UNMAPPED","OK")) -> OK | I2: =IF(A2="","",DATE(YEAR(A2),MONTH(A2),1)) -> 46023 | J2: =IF(B2="","",IF(G2="Revenue",N(E2)-N(D2),IF(OR(G2="COGS",G2="Opex"),N(D2)-N(E2),0))) -> 0
A3: 46027 | B3: 4000 | C3: Product sale | E3: 5000 | F3: {=IF($B3="","",IFERROR(INDEX(Accounts!$B$2:$B$100,MATCH($B3,Accounts!$A$2:$A$100,0)),""))} -> Product Sales | G3: {=IF($B3="","",IFERROR(INDEX(Accounts!$C$2:$C$100,MATCH($B3,Accounts!$A$2:$A$100,0)),""))} -> Revenue | H3: =IF($B3="","",IF(G3="","UNMAPPED","OK")) -> OK | I3: =IF(A3="","",DATE(YEAR(A3),MONTH(A3),1)) -> 46023 | J3: =IF(B3="","",IF(G3="Revenue",N(E3)-N(D3),IF(OR(G3="COGS",G3="Opex"),N(D3)-N(E3),0))) -> 5000
A4: 46032 | B4: 1000 | C4: Service income | D4: 2000 | F4: {=IF($B4="","",IFERROR(INDEX(Accounts!$B$2:$B$100,MATCH($B4,Accounts!$A$2:$A$100,0)),""))} -> Cash | G4: {=IF($B4="","",IFERROR(INDEX(Accounts!$C$2:$C$100,MATCH($B4,Accounts!$A$2:$A$100,0)),""))} -> Balance Sheet | H4: =IF($B4="","",IF(G4="","UNMAPPED","OK")) -> OK | I4: =IF(A4="","",DATE(YEAR(A4),MONTH(A4),1)) -> 46023 | J4: =IF(B4="","",IF(G4="Revenue",N(E4)-N(D4),IF(OR(G4="COGS",G4="Opex"),N(D4)-N(E4),0))) -> 0
A5: 46032 | B5: 4100 | C5: Service income | E5: 2000 | F5: {=IF($B5="","",IFERROR(INDEX(Accounts!$B$2:$B$100,MATCH($B5,Accounts!$A$2:$A$100,0)),""))} -> Service Revenue | G5: {=IF($B5="","",IFERROR(INDEX(Accounts!$C$2:$C$100,MATCH($B5,Accounts!$A$2:$A$100,0)),""))} -> Revenue | H5: =IF($B5="","",IF(G5="","UNMAPPED","OK")) -> OK | I5: =IF(A5="","",DATE(YEAR(A5),MONTH(A5),1)) -> 46023 | J5: =IF(B5="","",IF(G5="Revenue",N(E5)-N(D5),IF(OR(G5="COGS",G5="Opex"),N(D5)-N(E5),0))) -> 2000
A6: 46037 | B6: 5000 | C6: Cost of goods | D6: 1800 | F6: {=IF($B6="","",IFERROR(INDEX(Accounts!$B$2:$B$100,MATCH($B6,Accounts!$A$2:$A$100,0)),""))} -> Cost of Goods Sold | G6: {=IF($B6="","",IFERROR(INDEX(Accounts!$C$2:$C$100,MATCH($B6,Accounts!$A$2:$A$100,0)),""))} -> COGS | H6: =IF($B6="","",IF(G6="","UNMAPPED","OK")) -> OK | I6: =IF(A6="","",DATE(YEAR(A6),MONTH(A6),1)) -> 46023 | J6: =IF(B6="","",IF(G6="Revenue",N(E6)-N(D6),IF(OR(G6="COGS",G6="Opex"),N(D6)-N(E6),0))) -> 1800
A7: 46037 | B7: 1000 | C7: Cost of goods | E7: 1800 | F7: {=IF($B7="","",IFERROR(INDEX(Accounts!$B$2:$B$100,MATCH($B7,Accounts!$A$2:$A$100,0)),""))} -> Cash | G7: {=IF($B7="","",IFERROR(INDEX(Accounts!$C$2:$C$100,MATCH($B7,Accounts!$A$2:$A$100,0)),""))} -> Balance Sheet | H7: =IF($B7="","",IF(G7="","UNMAPPED","OK")) -> OK | I7: =IF(A7="","",DATE(YEAR(A7),MONTH(A7),1)) -> 46023 | J7: =IF(B7="","",IF(G7="Revenue",N(E7)-N(D7),IF(OR(G7="COGS",G7="Opex"),N(D7)-N(E7),0))) -> 0
A8: 46050 | B8: 6000 | C8: Salaries | D8: 2500 | F8: {=IF($B8="","",IFERROR(INDEX(Accounts!$B$2:$B$100,MATCH($B8,Accounts!$A$2:$A$100,0)),""))} -> Salaries | G8: {=IF($B8="","",IFERROR(INDEX(Accounts!$C$2:$C$100,MATCH($B8,Accounts!$A$2:$A$100,0)),""))} -> Opex | H8: =IF($B8="","",IF(G8="","UNMAPPED","OK")) -> OK | I8: =IF(A8="","",DATE(YEAR(A8),MONTH(A8),1)) -> 46023 | J8: =IF(B8="","",IF(G8="Revenue",N(E8)-N(D8),IF(OR(G8="COGS",G8="Opex"),N(D8)-N(E8),0))) -> 2500
A9: 46050 | B9: 1000 | C9: Salaries | E9: 2500 | F9: {=IF($B9="","",IFERROR(INDEX(Accounts!$B$2:$B$100,MATCH($B9,Accounts!$A$2:$A$100,0)),""))} -> Cash | G9: {=IF($B9="","",IFERROR(INDEX(Accounts!$C$2:$C$100,MATCH($B9,Accounts!$A$2:$A$100,0)),""))} -> Balance Sheet | H9: =IF($B9="","",IF(G9="","UNMAPPED","OK")) -> OK | I9: =IF(A9="","",DATE(YEAR(A9),MONTH(A9),1)) -> 46023 | J9: =IF(B9="","",IF(G9="Revenue",N(E9)-N(D9),IF(OR(G9="COGS",G9="Opex"),N(D9)-N(E9),0))) -> 0
A10: 46052 | B10: 6100 | C10: Rent | D10: 1000 | F10: {=IF($B10="","",IFERROR(INDEX(Accounts!$B$2:$B$100,MATCH($B10,Accounts!$A$2:$A$100,0)),""))} -> Rent | G10: {=IF($B10="","",IFERROR(INDEX(Accounts!$C$2:$C$100,MATCH($B10,Accounts!$A$2:$A$100,0)),""))} -> Opex | H10: =IF($B10="","",IF(G10="","UNMAPPED","OK")) -> OK | I10: =IF(A10="","",DATE(YEAR(A10),MONTH(A10),1)) -> 46023 | J10: =IF(B10="","",IF(G10="Revenue",N(E10)-N(D10),IF(OR(G10="COGS",G10="Opex"),N(D10)-N(E10),0))) -> 1000
A11: 46052 | B11: 1000 | C11: Rent | E11: 1000 | F11: {=IF($B11="","",IFERROR(INDEX(Accounts!$B$2:$B$100,MATCH($B11,Accounts!$A$2:$A$100,0)),""))} -> Cash | G11: {=IF($B11="","",IFERROR(INDEX(Accounts!$C$2:$C$100,MATCH($B11,Accounts!$A$2:$A$100,0)),""))} -> Balance Sheet | H11: =IF($B11="","",IF(G11="","UNMAPPED","OK")) -> OK | I11: =IF(A11="","",DATE(YEAR(A11),MONTH(A11),1)) -> 46023 | J11: =IF(B11="","",IF(G11="Revenue",N(E11)-N(D11),IF(OR(G11="COGS",G11="Opex"),N(D11)-N(E11),0))) -> 0
A12: 46056 | B12: 1000 | C12: Bank loan received | D12: 10000 | F12: {=IF($B12="","",IFERROR(INDEX(Accounts!$B$2:$B$100,MATCH($B12,Accounts!$A$2:$A$100,0)),""))} -> Cash | G12: {=IF($B12="","",IFERROR(INDEX(Accounts!$C$2:$C$100,MATCH($B12,Accounts!$A$2:$A$100,0)),""))} -> Balance Sheet | H12: =IF($B12="","",IF(G12="","UNMAPPED","OK")) -> OK | I12: =IF(A12="","",DATE(YEAR(A12),MONTH(A12),1)) -> 46054 | J12: =IF(B12="","",IF(G12="Revenue",N(E12)-N(D12),IF(OR(G12="COGS",G12="Opex"),N(D12)-N(E12),0))) -> 0
A13: 46056 | B13: 2500 | C13: Bank loan received | E13: 10000 | F13: {=IF($B13="","",IFERROR(INDEX(Accounts!$B$2:$B$100,MATCH($B13,Accounts!$A$2:$A$100,0)),""))} -> Bank Loan | G13: {=IF($B13="","",IFERROR(INDEX(Accounts!$C$2:$C$100,MATCH($B13,Accounts!$A$2:$A$100,0)),""))} -> Balance Sheet | H13: =IF($B13="","",IF(G13="","UNMAPPED","OK")) -> OK | I13: =IF(A13="","",DATE(YEAR(A13),MONTH(A13),1)) -> 46054 | J13: =IF(B13="","",IF(G13="Revenue",N(E13)-N(D13),IF(OR(G13="COGS",G13="Opex"),N(D13)-N(E13),0))) -> 0
A14: 46061 | B14: 1000 | C14: Product sale | D14: 6000 | F14: {=IF($B14="","",IFERROR(INDEX(Accounts!$B$2:$B$100,MATCH($B14,Accounts!$A$2:$A$100,0)),""))} -> Cash | G14: {=IF($B14="","",IFERROR(INDEX(Accounts!$C$2:$C$100,MATCH($B14,Accounts!$A$2:$A$100,0)),""))} -> Balance Sheet | H14: =IF($B14="","",IF(G14="","UNMAPPED","OK")) -> OK | I14: =IF(A14="","",DATE(YEAR(A14),MONTH(A14),1)) -> 46054 | J14: =IF(B14="","",IF(G14="Revenue",N(E14)-N(D14),IF(OR(G14="COGS",G14="Opex"),N(D14)-N(E14),0))) -> 0
A15: 46061 | B15: 4000 | C15: Product sale | E15: 6000 | F15: {=IF($B15="","",IFERROR(INDEX(Accounts!$B$2:$B$100,MATCH($B15,Accounts!$A$2:$A$100,0)),""))} -> Product Sales | G15: {=IF($B15="","",IFERROR(INDEX(Accounts!$C$2:$C$100,MATCH($B15,Accounts!$A$2:$A$100,0)),""))} -> Revenue | H15: =IF($B15="","",IF(G15="","UNMAPPED","OK")) -> OK | I15: =IF(A15="","",DATE(YEAR(A15),MONTH(A15),1)) -> 46054 | J15: =IF(B15="","",IF(G15="Revenue",N(E15)-N(D15),IF(OR(G15="COGS",G15="Opex"),N(D15)-N(E15),0))) -> 6000
A16: 46068 | B16: 6200 | C16: Marketing | D16: 800 | F16: {=IF($B16="","",IFERROR(INDEX(Accounts!$B$2:$B$100,MATCH($B16,Accounts!$A$2:$A$100,0)),""))} -> Marketing | G16: {=IF($B16="","",IFERROR(INDEX(Accounts!$C$2:$C$100,MATCH($B16,Accounts!$A$2:$A$100,0)),""))} -> Opex | H16: =IF($B16="","",IF(G16="","UNMAPPED","OK")) -> OK | I16: =IF(A16="","",DATE(YEAR(A16),MONTH(A16),1)) -> 46054 | J16: =IF(B16="","",IF(G16="Revenue",N(E16)-N(D16),IF(OR(G16="COGS",G16="Opex"),N(D16)-N(E16),0))) -> 800
A17: 46068 | B17: 1000 | C17: Marketing | E17: 800 | F17: {=IF($B17="","",IFERROR(INDEX(Accounts!$B$2:$B$100,MATCH($B17,Accounts!$A$2:$A$100,0)),""))} -> Cash | G17: {=IF($B17="","",IFERROR(INDEX(Accounts!$C$2:$C$100,MATCH($B17,Accounts!$A$2:$A$100,0)),""))} -> Balance Sheet | H17: =IF($B17="","",IF(G17="","UNMAPPED","OK")) -> OK | I17: =IF(A17="","",DATE(YEAR(A17),MONTH(A17),1)) -> 46054 | J17: =IF(B17="","",IF(G17="Revenue",N(E17)-N(D17),IF(OR(G17="COGS",G17="Opex"),N(D17)-N(E17),0))) -> 0
A18: 46081 | B18: 6000 | C18: Salaries | D18: 2500 | F18: {=IF($B18="","",IFERROR(INDEX(Accounts!$B$2:$B$100,MATCH($B18,Accounts!$A$2:$A$100,0)),""))} -> Salaries | G18: {=IF($B18="","",IFERROR(INDEX(Accounts!$C$2:$C$100,MATCH($B18,Accounts!$A$2:$A$100,0)),""))} -> Opex | H18: =IF($B18="","",IF(G18="","UNMAPPED","OK")) -> OK | I18: =IF(A18="","",DATE(YEAR(A18),MONTH(A18),1)) -> 46054 | J18: =IF(B18="","",IF(G18="Revenue",N(E18)-N(D18),IF(OR(G18="COGS",G18="Opex"),N(D18)-N(E18),0))) -> 2500
A19: 46081 | B19: 1000 | C19: Salaries | E19: 2500 | F19: {=IF($B19="","",IFERROR(INDEX(Accounts!$B$2:$B$100,MATCH($B19,Accounts!$A$2:$A$100,0)),""))} -> Cash | G19: {=IF($B19="","",IFERROR(INDEX(Accounts!$C$2:$C$100,MATCH($B19,Accounts!$A$2:$A$100,0)),""))} -> Balance Sheet | H19: =IF($B19="","",IF(G19="","UNMAPPED","OK")) -> OK | I19: =IF(A19="","",DATE(YEAR(A19),MONTH(A19),1)) -> 46054 | J19: =IF(B19="","",IF(G19="Revenue",N(E19)-N(D19),IF(OR(G19="COGS",G19="Opex"),N(D19)-N(E19),0))) -> 0
A20: 46086 | B20: 1000 | C20: Product sale | D20: 7000 | F20: {=IF($B20="","",IFERROR(INDEX(Accounts!$B$2:$B$100,MATCH($B20,Accounts!$A$2:$A$100,0)),""))} -> Cash | G20: {=IF($B20="","",IFERROR(INDEX(Accounts!$C$2:$C$100,MATCH($B20,Accounts!$A$2:$A$100,0)),""))} -> Balance Sheet | H20: =IF($B20="","",IF(G20="","UNMAPPED","OK")) -> OK | I20: =IF(A20="","",DATE(YEAR(A20),MONTH(A20),1)) -> 46082 | J20: =IF(B20="","",IF(G20="Revenue",N(E20)-N(D20),IF(OR(G20="COGS",G20="Opex"),N(D20)-N(E20),0))) -> 0
A21: 46086 | B21: 4000 | C21: Product sale | E21: 7000 | F21: {=IF($B21="","",IFERROR(INDEX(Accounts!$B$2:$B$100,MATCH($B21,Accounts!$A$2:$A$100,0)),""))} -> Product Sales | G21: {=IF($B21="","",IFERROR(INDEX(Accounts!$C$2:$C$100,MATCH($B21,Accounts!$A$2:$A$100,0)),""))} -> Revenue | H21: =IF($B21="","",IF(G21="","UNMAPPED","OK")) -> OK | I21: =IF(A21="","",DATE(YEAR(A21),MONTH(A21),1)) -> 46082 | J21: =IF(B21="","",IF(G21="Revenue",N(E21)-N(D21),IF(OR(G21="COGS",G21="Opex"),N(D21)-N(E21),0))) -> 7000
A22: 46093 | B22: 6900 | C22: Travel | D22: 400 | F22: {=IF($B22="","",IFERROR(INDEX(Accounts!$B$2:$B$100,MATCH($B22,Accounts!$A$2:$A$100,0)),""))} -> Travel | G22: {=IF($B22="","",IFERROR(INDEX(Accounts!$C$2:$C$100,MATCH($B22,Accounts!$A$2:$A$100,0)),""))} -> Opex | H22: =IF($B22="","",IF(G22="","UNMAPPED","OK")) -> OK | I22: =IF(A22="","",DATE(YEAR(A22),MONTH(A22),1)) -> 46082 | J22: =IF(B22="","",IF(G22="Revenue",N(E22)-N(D22),IF(OR(G22="COGS",G22="Opex"),N(D22)-N(E22),0))) -> 400
A23: 46093 | B23: 1000 | C23: Travel | E23: 400 | F23: {=IF($B23="","",IFERROR(INDEX(Accounts!$B$2:$B$100,MATCH($B23,Accounts!$A$2:$A$100,0)),""))} -> Cash | G23: {=IF($B23="","",IFERROR(INDEX(Accounts!$C$2:$C$100,MATCH($B23,Accounts!$A$2:$A$100,0)),""))} -> Balance Sheet | H23: =IF($B23="","",IF(G23="","UNMAPPED","OK")) -> OK | I23: =IF(A23="","",DATE(YEAR(A23),MONTH(A23),1)) -> 46082 | J23: =IF(B23="","",IF(G23="Revenue",N(E23)-N(D23),IF(OR(G23="COGS",G23="Opex"),N(D23)-N(E23),0))) -> 0
A24: 46109 | B24: 6000 | C24: Salaries | D24: 2500 | F24: {=IF($B24="","",IFERROR(INDEX(Accounts!$B$2:$B$100,MATCH($B24,Accounts!$A$2:$A$100,0)),""))} -> Salaries | G24: {=IF($B24="","",IFERROR(INDEX(Accounts!$C$2:$C$100,MATCH($B24,Accounts!$A$2:$A$100,0)),""))} -> Opex | H24: =IF($B24="","",IF(G24="","UNMAPPED","OK")) -> OK | I24: =IF(A24="","",DATE(YEAR(A24),MONTH(A24),1)) -> 46082 | J24: =IF(B24="","",IF(G24="Revenue",N(E24)-N(D24),IF(OR(G24="COGS",G24="Opex"),N(D24)-N(E24),0))) -> 2500
A25: 46109 | B25: 1000 | C25: Salaries | E25: 2500 | F25: {=IF($B25="","",IFERROR(INDEX(Accounts!$B$2:$B$100,MATCH($B25,Accounts!$A$2:$A$100,0)),""))} -> Cash | G25: {=IF($B25="","",IFERROR(INDEX(Accounts!$C$2:$C$100,MATCH($B25,Accounts!$A$2:$A$100,0)),""))} -> Balance Sheet | H25: =IF($B25="","",IF(G25="","UNMAPPED","OK")) -> OK | I25: =IF(A25="","",DATE(YEAR(A25),MONTH(A25),1)) -> 46082 | J25: =IF(B25="","",IF(G25="Revenue",N(E25)-N(D25),IF(OR(G25="COGS",G25="Opex"),N(D25)-N(E25),0))) -> 0
A26: 46116 | B26: 1000 | C26: Product sale | D26: 8000 | F26: {=IF($B26="","",IFERROR(INDEX(Accounts!$B$2:$B$100,MATCH($B26,Accounts!$A$2:$A$100,0)),""))} -> Cash | G26: {=IF($B26="","",IFERROR(INDEX(Accounts!$C$2:$C$100,MATCH($B26,Accounts!$A$2:$A$100,0)),""))} -> Balance Sheet | H26: =IF($B26="","",IF(G26="","UNMAPPED","OK")) -> OK | I26: =IF(A26="","",DATE(YEAR(A26),MONTH(A26),1)) -> 46113 | J26: =IF(B26="","",IF(G26="Revenue",N(E26)-N(D26),IF(OR(G26="COGS",G26="Opex"),N(D26)-N(E26),0))) -> 0
A27: 46116 | B27: 4000 | C27: Product sale | E27: 8000 | F27: {=IF($B27="","",IFERROR(INDEX(Accounts!$B$2:$B$100,MATCH($B27,Accounts!$A$2:$A$100,0)),""))} -> Product Sales | G27: {=IF($B27="","",IFERROR(INDEX(Accounts!$C$2:$C$100,MATCH($B27,Accounts!$A$2:$A$100,0)),""))} -> Revenue | H27: =IF($B27="","",IF(G27="","UNMAPPED","OK")) -> OK | I27: =IF(A27="","",DATE(YEAR(A27),MONTH(A27),1)) -> 46113 | J27: =IF(B27="","",IF(G27="Revenue",N(E27)-N(D27),IF(OR(G27="COGS",G27="Opex"),N(D27)-N(E27),0))) -> 8000
A28: 46127 | B28: 6200 | C28: Marketing | D28: 600 | F28: {=IF($B28="","",IFERROR(INDEX(Accounts!$B$2:$B$100,MATCH($B28,Accounts!$A$2:$A$100,0)),""))} -> Marketing | G28: {=IF($B28="","",IFERROR(INDEX(Accounts!$C$2:$C$100,MATCH($B28,Accounts!$A$2:$A$100,0)),""))} -> Opex | H28: =IF($B28="","",IF(G28="","UNMAPPED","OK")) -> OK | I28: =IF(A28="","",DATE(YEAR(A28),MONTH(A28),1)) -> 46113 | J28: =IF(B28="","",IF(G28="Revenue",N(E28)-N(D28),IF(OR(G28="COGS",G28="Opex"),N(D28)-N(E28),0))) -> 600
A29: 46127 | B29: 1000 | C29: Marketing | E29: 600 | F29: {=IF($B29="","",IFERROR(INDEX(Accounts!$B$2:$B$100,MATCH($B29,Accounts!$A$2:$A$100,0)),""))} -> Cash | G29: {=IF($B29="","",IFERROR(INDEX(Accounts!$C$2:$C$100,MATCH($B29,Accounts!$A$2:$A$100,0)),""))} -> Balance Sheet | H29: =IF($B29="","",IF(G29="","UNMAPPED","OK")) -> OK | I29: =IF(A29="","",DATE(YEAR(A29),MONTH(A29),1)) -> 46113 | J29: =IF(B29="","",IF(G29="Revenue",N(E29)-N(D29),IF(OR(G29="COGS",G29="Opex"),N(D29)-N(E29),0))) -> 0
A30: 46132 | B30: 6100 | C30: Rent | D30: 1000 | F30: {=IF($B30="","",IFERROR(INDEX(Accounts!$B$2:$B$100,MATCH($B30,Accounts!$A$2:$A$100,0)),""))} -> Rent | G30: {=IF($B30="","",IFERROR(INDEX(Accounts!$C$2:$C$100,MATCH($B30,Accounts!$A$2:$A$100,0)),""))} -> Opex | H30: =IF($B30="","",IF(G30="","UNMAPPED","OK")) -> OK | I30: =IF(A30="","",DATE(YEAR(A30),MONTH(A30),1)) -> 46113 | J30: =IF(B30="","",IF(G30="Revenue",N(E30)-N(D30),IF(OR(G30="COGS",G30="Opex"),N(D30)-N(E30),0))) -> 1000
A31: 46132 | B31: 1000 | C31: Rent | E31: 1000 | F31: {=IF($B31="","",IFERROR(INDEX(Accounts!$B$2:$B$100,MATCH($B31,Accounts!$A$2:$A$100,0)),""))} -> Cash | G31: {=IF($B31="","",IFERROR(INDEX(Accounts!$C$2:$C$100,MATCH($B31,Accounts!$A$2:$A$100,0)),""))} -> Balance Sheet | H31: =IF($B31="","",IF(G31="","UNMAPPED","OK")) -> OK | I31: =IF(A31="","",DATE(YEAR(A31),MONTH(A31),1)) -> 46113 | J31: =IF(B31="","",IF(G31="Revenue",N(E31)-N(D31),IF(OR(G31="COGS",G31="Opex"),N(D31)-N(E31),0))) -> 0
A32: 46140 | B32: 6000 | C32: Salaries | D32: 2500 | F32: {=IF($B32="","",IFERROR(INDEX(Accounts!$B$2:$B$100,MATCH($B32,Accounts!$A$2:$A$100,0)),""))} -> Salaries | G32: {=IF($B32="","",IFERROR(INDEX(Accounts!$C$2:$C$100,MATCH($B32,Accounts!$A$2:$A$100,0)),""))} -> Opex | H32: =IF($B32="","",IF(G32="","UNMAPPED","OK")) -> OK | I32: =IF(A32="","",DATE(YEAR(A32),MONTH(A32),1)) -> 46113 | J32: =IF(B32="","",IF(G32="Revenue",N(E32)-N(D32),IF(OR(G32="COGS",G32="Opex"),N(D32)-N(E32),0))) -> 2500
A33: 46140 | B33: 1000 | C33: Salaries | E33: 2500 | F33: {=IF($B33="","",IFERROR(INDEX(Accounts!$B$2:$B$100,MATCH($B33,Accounts!$A$2:$A$100,0)),""))} -> Cash | G33: {=IF($B33="","",IFERROR(INDEX(Accounts!$C$2:$C$100,MATCH($B33,Accounts!$A$2:$A$100,0)),""))} -> Balance Sheet | H33: =IF($B33="","",IF(G33="","UNMAPPED","OK")) -> OK | I33: =IF(A33="","",DATE(YEAR(A33),MONTH(A33),1)) -> 46113 | J33: =IF(B33="","",IF(G33="Revenue",N(E33)-N(D33),IF(OR(G33="COGS",G33="Opex"),N(D33)-N(E33),0))) -> 0
A34: 46096 | B34: 1100 | C34: Invoice to customer (unpaid) | D34: 5000 | F34: {=IF($B34="","",IFERROR(INDEX(Accounts!$B$2:$B$100,MATCH($B34,Accounts!$A$2:$A$100,0)),""))} -> Accounts Receivable | G34: {=IF($B34="","",IFERROR(INDEX(Accounts!$C$2:$C$100,MATCH($B34,Accounts!$A$2:$A$100,0)),""))} -> Balance Sheet | H34: =IF($B34="","",IF(G34="","UNMAPPED","OK")) -> OK | I34: =IF(A34="","",DATE(YEAR(A34),MONTH(A34),1)) -> 46082 | J34: =IF(B34="","",IF(G34="Revenue",N(E34)-N(D34),IF(OR(G34="COGS",G34="Opex"),N(D34)-N(E34),0))) -> 0
A35: 46096 | B35: 4100 | C35: Invoice to customer (unpaid) | E35: 5000 | F35: {=IF($B35="","",IFERROR(INDEX(Accounts!$B$2:$B$100,MATCH($B35,Accounts!$A$2:$A$100,0)),""))} -> Service Revenue | G35: {=IF($B35="","",IFERROR(INDEX(Accounts!$C$2:$C$100,MATCH($B35,Accounts!$A$2:$A$100,0)),""))} -> Revenue | H35: =IF($B35="","",IF(G35="","UNMAPPED","OK")) -> OK | I35: =IF(A35="","",DATE(YEAR(A35),MONTH(A35),1)) -> 46082 | J35: =IF(B35="","",IF(G35="Revenue",N(E35)-N(D35),IF(OR(G35="COGS",G35="Opex"),N(D35)-N(E35),0))) -> 5000
A36: 46101 | B36: 6200 | C36: Marketing bill (unpaid) | D36: 1200 | F36: {=IF($B36="","",IFERROR(INDEX(Accounts!$B$2:$B$100,MATCH($B36,Accounts!$A$2:$A$100,0)),""))} -> Marketing | G36: {=IF($B36="","",IFERROR(INDEX(Accounts!$C$2:$C$100,MATCH($B36,Accounts!$A$2:$A$100,0)),""))} -> Opex | H36: =IF($B36="","",IF(G36="","UNMAPPED","OK")) -> OK | I36: =IF(A36="","",DATE(YEAR(A36),MONTH(A36),1)) -> 46082 | J36: =IF(B36="","",IF(G36="Revenue",N(E36)-N(D36),IF(OR(G36="COGS",G36="Opex"),N(D36)-N(E36),0))) -> 1200
A37: 46101 | B37: 2000 | C37: Marketing bill (unpaid) | E37: 1200 | F37: {=IF($B37="","",IFERROR(INDEX(Accounts!$B$2:$B$100,MATCH($B37,Accounts!$A$2:$A$100,0)),""))} -> Accounts Payable | G37: {=IF($B37="","",IFERROR(INDEX(Accounts!$C$2:$C$100,MATCH($B37,Accounts!$A$2:$A$100,0)),""))} -> Balance Sheet | H37: =IF($B37="","",IF(G37="","UNMAPPED","OK")) -> OK | I37: =IF(A37="","",DATE(YEAR(A37),MONTH(A37),1)) -> 46082 | J37: =IF(B37="","",IF(G37="Revenue",N(E37)-N(D37),IF(OR(G37="COGS",G37="Opex"),N(D37)-N(E37),0))) -> 0
A38: 46122 | B38: 1000 | C38: Customer pays part of invoice | D38: 3000 | F38: {=IF($B38="","",IFERROR(INDEX(Accounts!$B$2:$B$100,MATCH($B38,Accounts!$A$2:$A$100,0)),""))} -> Cash | G38: {=IF($B38="","",IFERROR(INDEX(Accounts!$C$2:$C$100,MATCH($B38,Accounts!$A$2:$A$100,0)),""))} -> Balance Sheet | H38: =IF($B38="","",IF(G38="","UNMAPPED","OK")) -> OK | I38: =IF(A38="","",DATE(YEAR(A38),MONTH(A38),1)) -> 46113 | J38: =IF(B38="","",IF(G38="Revenue",N(E38)-N(D38),IF(OR(G38="COGS",G38="Opex"),N(D38)-N(E38),0))) -> 0
A39: 46122 | B39: 1100 | C39: Customer pays part of invoice | E39: 3000 | F39: {=IF($B39="","",IFERROR(INDEX(Accounts!$B$2:$B$100,MATCH($B39,Accounts!$A$2:$A$100,0)),""))} -> Accounts Receivable | G39: {=IF($B39="","",IFERROR(INDEX(Accounts!$C$2:$C$100,MATCH($B39,Accounts!$A$2:$A$100,0)),""))} -> Balance Sheet | H39: =IF($B39="","",IF(G39="","UNMAPPED","OK")) -> OK | I39: =IF(A39="","",DATE(YEAR(A39),MONTH(A39),1)) -> 46113 | J39: =IF(B39="","",IF(G39="Revenue",N(E39)-N(D39),IF(OR(G39="COGS",G39="Opex"),N(D39)-N(E39),0))) -> 0
A40: 46130 | B40: 2000 | C40: Supplier payment | D40: 700 | F40: {=IF($B40="","",IFERROR(INDEX(Accounts!$B$2:$B$100,MATCH($B40,Accounts!$A$2:$A$100,0)),""))} -> Accounts Payable | G40: {=IF($B40="","",IFERROR(INDEX(Accounts!$C$2:$C$100,MATCH($B40,Accounts!$A$2:$A$100,0)),""))} -> Balance Sheet | H40: =IF($B40="","",IF(G40="","UNMAPPED","OK")) -> OK | I40: =IF(A40="","",DATE(YEAR(A40),MONTH(A40),1)) -> 46113 | J40: =IF(B40="","",IF(G40="Revenue",N(E40)-N(D40),IF(OR(G40="COGS",G40="Opex"),N(D40)-N(E40),0))) -> 0
...
